<?xml version="1.0"?>
<robot name="myfirst">
  <link name="base_link">
    <visual>
      <geometry>
        <box size="0.38 0.38 0.19"/>
      </geometry>
      <material name="any">
        <color rgba="0 1 0 1"/>
      </material>
    </visual>
  </link>

  <link name="neck">
    <visual>
      <geometry>
        <box size="0.3 .015 .015"/>
      </geometry>
      <origin rpy="0 1.57075 0" xyz="-0.22 -0.16 -0.02"/>
      <material name="white">
        <color rgba="1 1 1 1"/>
      </material>
    </visual>
  </link>

  <joint name="base_to_neck" type="fixed">
    <parent link="base_link"/>
    <child link="neck"/>
    <origin xyz="0.22 0 .25"/>
  </joint>

  <link name="kinect_holder">
    <visual>
      <geometry>
        <box size="0.02 .08 .09"/>
      </geometry>
      <origin rpy="0 1.57075 0" xyz="-0.44 -0.16 -0.11"/>
      <material name="blue">
        <color rgba="0 0 .8 1"/>
      </material>
    </visual>
  </link>

  <joint name="neck_to_kinect_holder_holder" type="fixed">
    <parent link="neck"/>
    <child link="kinect_holder"/>
    <origin xyz="0.22 0 .25"/>
  </joint>

  <link name="front_wheel_holder">
    <visual>
      <geometry>
        <box size="0.05 .05 .05"/>
      </geometry>
      <origin rpy="0 1.57075 0" xyz="-0.22 -0.16 -0.35"/>
      <material name="white"/>
    </visual>
  </link>

  <joint name="base_to_front_wheel_holder" type="fixed">
    <parent link="base_link"/>
    <child link="front_wheel_holder"/>
    <origin xyz="0.22 0 .25"/>
  </joint>

  <link name="front__wheel">
    <visual>
      <geometry>
        <cylinder length=".04" radius="0.02"/>
      </geometry>
      <material name="black">
        <color rgba="0 0 0 1"/>
      </material>
    </visual>
  </link>

  <joint name="front__wheel_joint" type="continuous">
    <axis xyz="0 0 1"/>
    <parent link="front_wheel_holder"/>
    <child link="front__wheel"/>
    <origin rpy="0 1.57075 0" xyz="-0.22 -0.16 -0.40"/>
    <limit effort="100" velocity="10"/>
  </joint>

  <link name="right_leg">
    <visual>
      <geometry>
        <box size="0.06 .04 .04"/>
      </geometry>
      <origin rpy="0 1.57075 0" xyz="-0.03 0.12 -0.34"/>
      <material name="white"/>
    </visual>
  </link>

  <joint name="base_to_right_leg" type="fixed">
    <parent link="base_link"/>
    <child link="right_leg"/>
    <origin xyz="0.22 0 .25"/>
  </joint>

  <link name="right__wheel">
    <visual>
      <geometry>
        <cylinder length=".03" radius="0.08"/>
      </geometry>
      <material name="black"/>
    </visual>
  </link>

  <joint name="right__wheel_joint" type="continuous">
    <axis xyz="0 0 1"/>
    <parent link="right_leg"/>
    <child link="right__wheel"/>
    <origin rpy="0 1.57075 0" xyz="0 0.12 -0.34"/>
    <limit effort="100" velocity="10"/>
  </joint>

  <link name="left_leg">
    <visual>
      <geometry>
        <box size="0.06 .04 .04"/>
      </geometry>
      <origin rpy="0 1.57075 0" xyz="0.03 0.12 -0.34"/>
      <material name="white"/>
    </visual>
  </link>

  <joint name="base_to_left_leg" type="fixed">
    <parent link="base_link"/>
    <child link="left_leg"/>
    <origin xyz="-0.22 0 .25"/>
  </joint>

  <link name="left__wheel">
    <visual>
      <geometry>
        <cylinder length=".03" radius="0.08"/>
      </geometry>
      <material name="black"/>
    </visual>
  </link>

  <joint name="left__wheel_joint" type="continuous">
    <axis xyz="0 0 1"/>
    <parent link="left_leg"/>
    <child link="left__wheel"/>
    <origin rpy="0 1.57075 0" xyz="0 0.12 -0.34"/>
    <limit effort="100" velocity="10"/>
  </joint>
</robot>
